Workbook

Sheet FINAL
A1: Name | B1: Usage Rate | C1: Progressive Actions | D1: G+A | E1: State | F1: Value | G1: PrgC | H1: PrgP | I1: PrgR
A2: ='Sheet 1'!B1 -> Marshall Munetsi | B2: =('Sheet 1'!B108)+('Sheet 1'!B109)+(('Sheet 1'!B31)-('Sheet 1'!B30))+(('Sheet 1'!B98)-('Sheet 1'!B99))+('Sheet 1'!B20) -> 11.63 | C2: =('Sheet 1'!B17)+('Sheet 1'!B18)+('Sheet 1'!B19) -> 4.84 | D2: =('Sheet 1'!B5)+('Sheet 1'!B6) -> 0.26 | E2: Current | F2: 15 | G2: =('Sheet 1'!B17) -> 0.68 | H2: =('Sheet 1'!B18) -> 1.2 | I2: =('Sheet 1'!B19) -> 2.96
A3: ='Sheet 1'!D1 -> João Gomes | B3: =('Sheet 1'!D108)+('Sheet 1'!D109)+(('Sheet 1'!D31)-('Sheet 1'!D30))+(('Sheet 1'!D98)-('Sheet 1'!D99))+('Sheet 1'!D20) -> 12.99 | C3: =('Sheet 1'!D17)+('Sheet 1'!D18)+('Sheet 1'!D19) -> 9.47 | D3: =('Sheet 1'!D5)+('Sheet 1'!D6) -> 0.09 | E3: Current | F3: 40 | G3: =('Sheet 1'!D17) -> 1.57 | H3: =('Sheet 1'!D18) -> 5.63 | I3: =('Sheet 1'!D19) -> 2.27
A4: ='Sheet 1'!F1 -> Jean-Ricner Bellegarde | B4: =('Sheet 1'!F108)+('Sheet 1'!F109)+(('Sheet 1'!F31)-('Sheet 1'!F30))+(('Sheet 1'!F98)-('Sheet 1'!F99))+('Sheet 1'!F20) -> 15.26 | C4: =('Sheet 1'!F17)+('Sheet 1'!F18)+('Sheet 1'!F19) -> 10.6 | D4: =('Sheet 1'!F5)+('Sheet 1'!F6) -> 0.36 | E4: Current | F4: 18 | G4: =('Sheet 1'!F17) -> 3.03 | H4: =('Sheet 1'!F18) -> 3.34 | I4: =('Sheet 1'!F19) -> 4.23
A5: ='Sheet 1'!H1 -> André | B5: =('Sheet 1'!H108)+('Sheet 1'!H109)+(('Sheet 1'!H31)-('Sheet 1'!H30))+(('Sheet 1'!H98)-('Sheet 1'!H99))+('Sheet 1'!H20) -> 6.67 | C5: =('Sheet 1'!H17)+('Sheet 1'!H18)+('Sheet 1'!H19) -> 5.02 | D5: =('Sheet 1'!H5)+('Sheet 1'!H6) -> 0 | E5: Current | F5: 28 | G5: =('Sheet 1'!H17) -> 0.54 | H5: =('Sheet 1'!H18) -> 4.03 | I5: =('Sheet 1'!H19) -> 0.45
A6: ='Sheet 1'!J1 -> Ladislav Krejčí | B6: =('Sheet 1'!J108)+('Sheet 1'!J109)+(('Sheet 1'!J31)-('Sheet 1'!J30))+(('Sheet 1'!J98)-('Sheet 1'!J99))+('Sheet 1'!J20) -> 9.14 | C6: =('Sheet 1'!J17)+('Sheet 1'!J18)+('Sheet 1'!J19) -> 6.03 | D6: =('Sheet 1'!J5)+('Sheet 1'!J6) -> 0.12 | E6: Current | F6: 22 | G6: =('Sheet 1'!J17) -> 0.69 | H6: =('Sheet 1'!J18) -> 4.97 | I6: =('Sheet 1'!J19) -> 0.37
A7: ='Sheet 1'!L1 -> Tommy Doyle | B7: =('Sheet 1'!L108)+('Sheet 1'!L109)+(('Sheet 1'!L31)-('Sheet 1'!L30))+(('Sheet 1'!L98)-('Sheet 1'!L99))+('Sheet 1'!L20) -> 13.57 | C7: =('Sheet 1'!L17)+('Sheet 1'!L18)+('Sheet 1'!L19) -> 8.77 | D7: =('Sheet 1'!L5)+('Sheet 1'!L6) -> 0 | E7: Departed | F7: 10 | G7: =('Sheet 1'!L17) -> 1.55 | H7: =('Sheet 1'!L18) -> 5.97 | I7: =('Sheet 1'!L19) -> 1.25
A8: ='Sheet 1'!N1 -> Mario Lemina | B8: =('Sheet 1'!N108)+('Sheet 1'!N109)+(('Sheet 1'!N31)-('Sheet 1'!N30))+(('Sheet 1'!N98)-('Sheet 1'!N99))+('Sheet 1'!N20) -> 10.1 | C8: =('Sheet 1'!N17)+('Sheet 1'!N18)+('Sheet 1'!N19) -> 4.76 | D8: =('Sheet 1'!N5)+('Sheet 1'!N6) -> 0.15 | E8: Departed | F8: 10 | G8: =('Sheet 1'!N17) -> 0.97 | H8: =('Sheet 1'!N18) -> 2.3 | I8: =('Sheet 1'!N19) -> 1.49
A9: ='Sheet 1'!P1 -> Matheus Nunes | B9: =('Sheet 1'!P108)+('Sheet 1'!P109)+(('Sheet 1'!P31)-('Sheet 1'!P30))+(('Sheet 1'!P98)-('Sheet 1'!P99))+('Sheet 1'!P20) -> 13.09 | C9: =('Sheet 1'!P17)+('Sheet 1'!P18)+('Sheet 1'!P19) -> 9.92 | D9: =('Sheet 1'!P5)+('Sheet 1'!P6) -> 0.08 | E9: Departed | F9: 45 | G9: =('Sheet 1'!P17) -> 2.15 | H9: =('Sheet 1'!P18) -> 3.06 | I9: =('Sheet 1'!P19) -> 4.71
A10: ='Sheet 1'!R1 -> João Moutinho | B10: =('Sheet 1'!R108)+('Sheet 1'!R109)+(('Sheet 1'!R31)-('Sheet 1'!R30))+(('Sheet 1'!R98)-('Sheet 1'!R99))+('Sheet 1'!R20) -> 12.69 | C10: =('Sheet 1'!R17)+('Sheet 1'!R18)+('Sheet 1'!R19) -> 9.45 | D10: =('Sheet 1'!R5)+('Sheet 1'!R6) -> 0.1 | E10: Departed | F10: 10 | G10: =('Sheet 1'!R17) -> 1.16 | H10: =('Sheet 1'!R18) -> 6.67 | I10: =('Sheet 1'!R19) -> 1.62
A11: ='Sheet 1'!T1 -> Rúben Neves | B11: =('Sheet 1'!T108)+('Sheet 1'!T109)+(('Sheet 1'!T31)-('Sheet 1'!T30))+(('Sheet 1'!T98)-('Sheet 1'!T99))+('Sheet 1'!T20) -> 14.49 | C11: =('Sheet 1'!T17)+('Sheet 1'!T18)+('Sheet 1'!T19) -> 7.87 | D11: =('Sheet 1'!T5)+('Sheet 1'!T6) -> 0.21 | E11: Departed | F11: 50 | G11: =('Sheet 1'!T17) -> 0.83 | H11: =('Sheet 1'!T18) -> 6.5 | I11: =('Sheet 1'!T19) -> 0.54
A12: ='Sheet 1'!V1 -> Boubacar Traoré | B12: =('Sheet 1'!V108)+('Sheet 1'!V109)+(('Sheet 1'!V31)-('Sheet 1'!V30))+(('Sheet 1'!V98)-('Sheet 1'!V99))+('Sheet 1'!V20) -> 12.97 | C12: =('Sheet 1'!V17)+('Sheet 1'!V18)+('Sheet 1'!V19) -> 5.83 | D12: =('Sheet 1'!V5)+('Sheet 1'!V6) -> 0 | E12: Departed | F12: 5 | G12: =('Sheet 1'!V17) -> 0.99 | H12: =('Sheet 1'!V18) -> 3.19 | I12: =('Sheet 1'!V19) -> 1.65
A13: ='Sheet 1'!X1 -> Leander Dendoncker | B13: =('Sheet 1'!X108)+('Sheet 1'!X109)+(('Sheet 1'!X31)-('Sheet 1'!X30))+(('Sheet 1'!X98)-('Sheet 1'!X99))+('Sheet 1'!X20) -> 8.08 | C13: =('Sheet 1'!X17)+('Sheet 1'!X18)+('Sheet 1'!X19) -> 5.45 | D13: =('Sheet 1'!X5)+('Sheet 1'!X6) -> 0.18 | E13: Departed | F13: 30 | G13: =('Sheet 1'!X17) -> 0.42 | H13: =('Sheet 1'!X18) -> 2.95 | I13: =('Sheet 1'!X19) -> 2.08

Sheet Sheet 1
A1: Player | B1: Marshall Munetsi | D1: João Gomes | F1: Jean-Ricner Bellegarde | H1: André | J1: Ladislav Krejčí | L1: Tommy Doyle | N1: Mario Lemina | P1: Matheus Nunes | R1: João Moutinho | T1: Rúben Neves | V1: Boubacar Traoré | X1: Leander Dendoncker
A4: Stat | B4: Per90 | C4: Percentile | D4: Per90 | E4: Percentile | F4: Per90 | G4: Percentile | H4: Per90 | I4: Percentile | J4: Per90 | K4: Percentile | L4: Per90 | M4: Percentile | N4: Per90 | O4: Percentile | P4: Per90 | Q4: Percentile | R4: Per90 | S4: Percentile | T4: Per90 | U4: Percentile | V4: Per90 | W4: Percentile | X4: Per90 | Y4: Percentile
A5: Goals | B5: =IFERROR(INDIRECT("'" & SUBSTITUTE($B$1,"'","''") & "'!B2"), "") -> 0.13 | C5: =IFERROR(INDIRECT("'" & SUBSTITUTE($B$1,"'","''") & "'!C2"), "") -> 74 | D5: =IFERROR(INDIRECT("'" & SUBSTITUTE($D$1,"'","''") & "'!B2"), "") -> 0.06 | E5: =IFERROR(INDIRECT("'" & SUBSTITUTE($D$1,"'","''") & "'!C2"), "") -> 45 | F5: =IFERROR(INDIRECT("'" & SUBSTITUTE($F$1,"'","''") & "'!B2"), "") -> 0.05 | G5: =IFERROR(INDIRECT("'" & SUBSTITUTE($F$1,"'","''") & "'!C2"), "") -> 38 | H5: =IFERROR(INDIRECT("'" & SUBSTITUTE($H$1,"'","''") & "'!B2"), "") -> 0 | I5: =IFERROR(INDIRECT("'" & SUBSTITUTE($H$1,"'","''") & "'!C2"), "") -> 11 | J5: =IFERROR(INDIRECT("'" & SUBSTITUTE($J$1,"'","''") & "'!B2"), "") -> 0.09 | K5: =IFERROR(INDIRECT("'" & SUBSTITUTE($J$1,"'","''") & "'!C2"), "") -> 80 | L5: =IFERROR(INDIRECT("'" & SUBSTITUTE($L$1,"'","''") & "'!B2"), "") -> 0 | M5: =IFERROR(INDIRECT("'" & SUBSTITUTE($L$1,"'","''") & "'!C2"), "") -> 14 | N5: =IFERROR(INDIRECT("'" & SUBSTITUTE($N$1,"'","''") & "'!B2"), "") -> 0.12 | O5: =IFERROR(INDIRECT("'" & SUBSTITUTE($N$1,"'","''") & "'!C2"), "") -> 64 | P5: =IFERROR(INDIRECT("'" & SUBSTITUTE($P$1,"'","''") & "'!B2"), "") -> 0.04 | Q5: =IFERROR(INDIRECT("'" & SUBSTITUTE($P$1,"'","''") & "'!C2"), "") -> 36 | R5: =IFERROR(INDIRECT("'" & SUBSTITUTE($R$1,"'","''") & "'!B2"), "") -> 0 | S5: =IFERROR(INDIRECT("'" & SUBSTITUTE($R$1,"'","''") & "'!C2"), "") -> 16 | T5: =IFERROR(INDIRECT("'" & SUBSTITUTE($T$1,"'","''") & "'!B2"), "") -> 0.18 | U5: =IFERROR(INDIRECT("'" & SUBSTITUTE($T$1,"'","''") & "'!C2"), "") -> 77 | V5: =IFERROR(INDIRECT("'" & SUBSTITUTE($V$1,"'","''") & "'!B2"), "") -> 0 | W5: =IFERROR(INDIRECT("'" & SUBSTITUTE($V$1,"'","''") & "'!C2"), "") -> 14 | X5: =IFERROR(INDIRECT("'" & SUBSTITUTE($X$1,"'","''") & "'!B2"), "") -> 0.09 | Y5: =IFERROR(INDIRECT("'" & SUBSTITUTE($X$1,"'","''") & "'!C2"), "") -> 62
A6: Assists | B6: =IFERROR(INDIRECT("'" & SUBSTITUTE($B$1,"'","''") & "'!B5"), "") -> 0.13 | C6: =IFERROR(INDIRECT("'" & SUBSTITUTE($B$1,"'","''") & "'!C5"), "") -> 71 | D6: =IFERROR(INDIRECT("'" & SUBSTITUTE($D$1,"'","''") & "'!B5"), "") -> 0.03 | E6: =IFERROR(INDIRECT("'" & SUBSTITUTE($D$1,"'","''") & "'!C5"), "") -> 21 | F6: =IFERROR(INDIRECT("'" & SUBSTITUTE($F$1,"'","''") & "'!B5"), "") -> 0.31 | G6: =IFERROR(INDIRECT("'" & SUBSTITUTE($F$1,"'","''") & "'!C5"), "") -> 98 | H6: =IFERROR(INDIRECT("'" & SUBSTITUTE($H$1,"'","''") & "'!B5"), "") -> 0 | I6: =IFERROR(INDIRECT("'" & SUBSTITUTE($H$1,"'","''") & "'!C5"), "") -> 9 | J6: =IFERROR(INDIRECT("'" & SUBSTITUTE($J$1,"'","''") & "'!B5"), "") -> 0.03 | K6: =IFERROR(INDIRECT("'" & SUBSTITUTE($J$1,"'","''") & "'!C5"), "") -> 58 | L6: =IFERROR(INDIRECT("'" & SUBSTITUTE($L$1,"'","''") & "'!B5"), "") -> 0 | M6: =IFERROR(INDIRECT("'" & SUBSTITUTE($L$1,"'","''") & "'!C5"), "") -> 13 | N6: =IFERROR(INDIRECT("'" & SUBSTITUTE($N$1,"'","''") & "'!B5"), "") -> 0.03 | O6: =IFERROR(INDIRECT("'" & SUBSTITUTE($N$1,"'","''") & "'!C5"), "") -> 27 | P6: =IFERROR(INDIRECT("'" & SUBSTITUTE($P$1,"'","''") & "'!B5"), "") -> 0.04 | Q6: =IFERROR(INDIRECT("'" & SUBSTITUTE($P$1,"'","''") & "'!C5"), "") -> 33 | R6: =IFERROR(INDIRECT("'" & SUBSTITUTE($R$1,"'","''") & "'!B5"), "") -> 0.1 | S6: =IFERROR(INDIRECT("'" & SUBSTITUTE($R$1,"'","''") & "'!C5"), "") -> 59 | T6: =IFERROR(INDIRECT("'" & SUBSTITUTE($T$1,"'","''") & "'!B5"), "") -> 0.03 | U6: =IFERROR(INDIRECT("'" & SUBSTITUTE($T$1,"'","''") & "'!C5"), "") -> 28 | V6: =IFERROR(INDIRECT("'" & SUBSTITUTE($V$1,"'","''") & "'!B5"), "") -> 0 | W6: =IFERROR(INDIRECT("'" & SUBSTITUTE($V$1,"'","''") & "'!C5"), "") -> 13 | X6: =IFERROR(INDIRECT("'" & SUBSTITUTE($X$1,"'","''") & "'!B5"), "") -> 0.09 | Y6: =IFERROR(INDIRECT("'" & SUBSTITUTE($X$1,"'","''") & "'!C5"), "") -> 58
A7: Goals + Assists | B7: =IFERROR(INDIRECT("'" & SUBSTITUTE($B$1,"'","''") & "'!B8"), "") -> 0.26 | C7: =IFERROR(INDIRECT("'" & SUBSTITUTE($B$1,"'","''") & "'!C8"), "") -> 73 | D7: =IFERROR(INDIRECT("'" & SUBSTITUTE($D$1,"'","''") & "'!B8"), "") -> 0.09 | E7: =IFERROR(INDIRECT("'" & SUBSTITUTE($D$1,"'","''") & "'!C8"), "") -> 26 | F7: =IFERROR(INDIRECT("'" & SUBSTITUTE($F$1,"'","''") & "'!B8"), "") -> 0.37 | G7: =IFERROR(INDIRECT("'" & SUBSTITUTE($F$1,"'","''") & "'!C8"), "") -> 87 | H7: =IFERROR(INDIRECT("'" & SUBSTITUTE($H$1,"'","''") & "'!B8"), "") -> 0 | I7: =IFERROR(INDIRECT("'" & SUBSTITUTE($H$1,"'","''") & "'!C8"), "") -> 3 | J7: =IFERROR(INDIRECT("'" & SUBSTITUTE($J$1,"'","''") & "'!B8"), "") -> 0.11 | K7: =IFERROR(INDIRECT("'" & SUBSTITUTE($J$1,"'","''") & "'!C8"), "") -> 78 | L7: =IFERROR(INDIRECT("'" & SUBSTITUTE($L$1,"'","''") & "'!B8"), "") -> 0 | M7: =IFERROR(INDIRECT("'" & SUBSTITUTE($L$1,"'","''") & "'!C8"), "") -> 7 | N7: =IFERROR(INDIRECT("'" & SUBSTITUTE($N$1,"'","''") & "'!B8"), "") -> 0.15 | O7: =IFERROR(INDIRECT("'" & SUBSTITUTE($N$1,"'","''") & "'!C8"), "") -> 42 | P7: =IFERROR(INDIRECT("'" & SUBSTITUTE($P$1,"'","''") & "'!B8"), "") -> 0.07 | Q7: =IFERROR(INDIRECT("'" & SUBSTITUTE($P$1,"'","''") & "'!C8"), "") -> 23 | R7: =IFERROR(INDIRECT("'" & SUBSTITUTE($R$1,"'","''") & "'!B8"), "") -> 0.1 | S7: =IFERROR(INDIRECT("'" & SUBSTITUTE($R$1,"'","''") & "'!C8"), "") -> 32 | T7: =IFERROR(INDIRECT("'" & SUBSTITUTE($T$1,"'","''") & "'!B8"), "") -> 0.21 | U7: =IFERROR(INDIRECT("'" & SUBSTITUTE($T$1,"'","''") & "'!C8"), "") -> 60 | V7: =IFERROR(INDIRECT("'" & SUBSTITUTE($V$1,"'","''") & "'!B8"), "") -> 0 | W7: =IFERROR(INDIRECT("'" & SUBSTITUTE($V$1,"'","''") & "'!C8"), "") -> 7 | X7: =IFERROR(INDIRECT("'" & SUBSTITUTE($X$1,"'","''") & "'!B8"), "") -> 0.18 | Y7: =IFERROR(INDIRECT("'" & SUBSTITUTE($X$1,"'","''") & "'!C8"), "") -> 57
A8: Non-Penalty Goals | B8: =IFERROR(INDIRECT("'" & SUBSTITUTE($B$1,"'","''") & "'!B11"), "") -> 0.13 | C8: =IFERROR(INDIRECT("'" & SUBSTITUTE($B$1,"'","''") & "'!C11"), "") -> 76 | D8: =IFERROR(INDIRECT("'" & SUBSTITUTE($D$1,"'","''") & "'!B11"), "") -> 0.06 | E8: =IFERROR(INDIRECT("'" & SUBSTITUTE($D$1,"'","''") & "'!C11"), "") -> 47 | F8: =IFERROR(INDIRECT("'" & SUBSTITUTE($F$1,"'","''") & "'!B11"), "") -> 0.05 | G8: =IFERROR(INDIRECT("'" & SUBSTITUTE($F$1,"'","''") & "'!C11"), "") -> 39 | H8: =IFERROR(INDIRECT("'" & SUBSTITUTE($H$1,"'","''") & "'!B11"), "") -> 0 | I8: =IFERROR(INDIRECT("'" & SUBSTITUTE($H$1,"'","''") & "'!C11"), "") -> 11 | J8: =IFERROR(INDIRECT("'" & SUBSTITUTE($J$1,"'","''") & "'!B11"), "") -> 0.09 | K8: =IFERROR(INDIRECT("'" & SUBSTITUTE($J$1,"'","''") & "'!C11"), "") -> 81 | L8: =IFERROR(INDIRECT("'" & SUBSTITUTE($L$1,"'","''") & "'!B11"), "") -> 0 | M8: =IFERROR(INDIRECT("'" & SUBSTITUTE($L$1,"'","''") & "'!C11"), "") -> 14 | N8: =IFERROR(INDIRECT("'" & SUBSTITUTE($N$1,"'","''") & "'!B11"), "") -> 0.12 | O8: =IFERROR(INDIRECT("'" & SUBSTITUTE($N$1,"'","''") & "'!C11"), "") -> 67 | P8: =IFERROR(INDIRECT("'" & SUBSTITUTE($P$1,"'","''") & "'!B11"), "") -> 0.04 | Q8: =IFERROR(INDIRECT("'" & SUBSTITUTE($P$1,"'","''") & "'!C11"), "") -> 37 | R8: =IFERROR(INDIRECT("'" & SUBSTITUTE($R$1,"'","''") & "'!B11"), "") -> 0 | S8: =IFERROR(INDIRECT("'" & SUBSTITUTE($R$1,"'","''") & "'!C11"), "") -> 16 | T8: =IFERROR(INDIRECT("'" & SUBSTITUTE($T$1,"'","''") & "'!B11"), "") -> 0.09 | U8: =IFERROR(INDIRECT("'" & SUBSTITUTE($T$1,"'","''") & "'!C11"), "") -> 55 | V8: =IFERROR(INDIRECT("'" & SUBSTITUTE($V$1,"'","''") & "'!B11"), "") -> 0 | W8: =IFERROR(INDIRECT("'" & SUBSTITUTE($V$1,"'","''") & "'!C11"), "") -> 14 | X8: =IFERROR(INDIRECT("'" & SUBSTITUTE($X$1,"'","''") & "'!B11"), "") -> 0.09 | Y8: =IFERROR(INDIRECT("'" & SUBSTITUTE($X$1,"'","''") & "'!C11"), "") -> 63
A9: Penalty Kicks Made | B9: =IFERROR(INDIRECT("'" & SUBSTITUTE($B$1,"'","''") & "'!B14"), "") -> 0 | C9: =IFERROR(INDIRECT("'" & SUBSTITUTE($B$1,"'","''") & "'!C14"), "") -> 45 | D9: =IFERROR(INDIRECT("'" & SUBSTITUTE($D$1,"'","''") & "'!B14"), "") -> 0 | E9: =IFERROR(INDIRECT("'" & SUBSTITUTE($D$1,"'","''") & "'!C14"), "") -> 45 | F9: =IFERROR(INDIRECT("'" & SUBSTITUTE($F$1,"'","''") & "'!B14"), "") -> 0 | G9: =IFERROR(INDIRECT("'" & SUBSTITUTE($F$1,"'","''") & "'!C14"), "") -> 45 | H9: =IFERROR(INDIRECT("'" & SUBSTITUTE($H$1,"'","''") & "'!B14"), "") -> 0 | I9: =IFERROR(INDIRECT("'" & SUBSTITUTE($H$1,"'","''") & "'!C14"), "") -> 45 | J9: =IFERROR(INDIRECT("'" & SUBSTITUTE($J$1,"'","''") & "'!B14"), "") -> 0 | K9: =IFERROR(INDIRECT("'" & SUBSTITUTE($J$1,"'","''") & "'!C14"), "") -> 49 | L9: =IFERROR(INDIRECT("'" & SUBSTITUTE($L$1,"'","''") & "'!B14"), "") -> 0 | M9: =IFERROR(INDIRECT("'" & SUBSTITUTE($L$1,"'","''") & "'!C14"), "") -> 45 | N9: =IFERROR(INDIRECT("'" & SUBSTITUTE($N$1,"'","''") & "'!B14"), "") -> 0 | O9: =IFERROR(INDIRECT("'" & SUBSTITUTE($N$1,"'","''") & "'!C14"), "") -> 45 | P9: =IFERROR(INDIRECT("'" & SUBSTITUTE($P$1,"'","''") & "'!B14"), "") -> 0 | Q9: =IFERROR(INDIRECT("'" & SUBSTITUTE($P$1,"'","''") & "'!C14"), "") -> 46 | R9: =IFERROR(INDIRECT("'" & SUBSTITUTE($R$1,"'","''") & "'!B14"), "") -> 0 | S9: =IFERROR(INDIRECT("'" & SUBSTITUTE($R$1,"'","''") & "'!C14"), "") -> 46 | T9: =IFERROR(INDIRECT("'" & SUBSTITUTE($T$1,"'","''") & "'!B14"), "") -> 0.09 | U9: =IFERROR(INDIRECT("'" & SUBSTITUTE($T$1,"'","''") & "'!C14"), "") -> 99 | V9: =IFERROR(INDIRECT("'" & SUBSTITUTE($V$1,"'","''") & "'!B14"), "") -> 0 | W9: =IFERROR(INDIRECT("'" & SUBSTITUTE($V$1,"'","''") & "'!C14"), "") -> 45 | X9: =IFERROR(INDIRECT("'" & SUBSTITUTE($X$1,"'","''") & "'!B14"), "") -> 0 | Y9: =IFERROR(INDIRECT("'" & SUBSTITUTE($X$1,"'","''") & "'!C14"), "") -> 46
A10: Penalty Kicks Attempted | B10: =IFERROR(INDIRECT("'" & SUBSTITUTE($B$1,"'","''") & "'!B17"), "") -> 0 | C10: =IFERROR(INDIRECT("'" & SUBSTITUTE($B$1,"'","''") & "'!C17"), "") -> 44 | D10: =IFERROR(INDIRECT("'" & SUBSTITUTE($D$1,"'","''") & "'!B17"), "") -> 0 | E10: =IFERROR(INDIRECT("'" & SUBSTITUTE($D$1,"'","''") & "'!C17"), "") -> 44 | F10: =IFERROR(INDIRECT("'" & SUBSTITUTE($F$1,"'","''") & "'!B17"), "") -> 0 | G10: =IFERROR(INDIRECT("'" & SUBSTITUTE($F$1,"'","''") & "'!C17"), "") -> 44 | H10: =IFERROR(INDIRECT("'" & SUBSTITUTE($H$1,"'","''") & "'!B17"), "") -> 0 | I10: =IFERROR(INDIRECT("'" & SUBSTITUTE($H$1,"'","''") & "'!C17"), "") -> 44 | J10: =IFERROR(INDIRECT("'" & SUBSTITUTE($J$1,"'","''") & "'!B17"), "") -> 0 | K10: =IFERROR(INDIRECT("'" & SUBSTITUTE($J$1,"'","''") & "'!C17"), "") -> 49 | L10: =IFERROR(INDIRECT("'" & SUBSTITUTE($L$1,"'","''") & "'!B17"), "") -> 0 | M10: =IFERROR(INDIRECT("'" & SUBSTITUTE($L$1,"'","''") & "'!C17"), "") -> 45 | N10: =IFERROR(INDIRECT("'" & SUBSTITUTE($N$1,"'","''") & "'!B17"), "") -> 0 | O10: =IFERROR(INDIRECT("'" & SUBSTITUTE($N$1,"'","''") & "'!C17"), "") -> 45 | P10: =IFERROR(INDIRECT("'" & SUBSTITUTE($P$1,"'","''") & "'!B17"), "") -> 0 | Q10: =IFERROR(INDIRECT("'" & SUBSTITUTE($P$1,"'","''") & "'!C17"), "") -> 45 | R10: =IFERROR(INDIRECT("'" & SUBSTITUTE($R$1,"'","''") & "'!B17"), "") -> 0 | S10: =IFERROR(INDIRECT("'" & SUBSTITUTE($R$1,"'","''") & "'!C17"), "") -> 45 | T10: =IFERROR(INDIRECT("'" & SUBSTITUTE($T$1,"'","''") & "'!B17"), "") -> 0.09 | U10: =IFERROR(INDIRECT("'" & SUBSTITUTE($T$1,"'","''") & "'!C17"), "") -> 98 | V10: =IFERROR(INDIRECT("'" & SUBSTITUTE($V$1,"'","''") & "'!B17"), "") -> 0 | W10: =IFERROR(INDIRECT("'" & SUBSTITUTE($V$1,"'","''") & "'!C17"), "") -> 45 | X10: =IFERROR(INDIRECT("'" & SUBSTITUTE($X$1,"'","''") & "'!B17"), "") -> 0 | Y10: =IFERROR(INDIRECT("'" & SUBSTITUTE($X$1,"'","''") & "'!C17"), "") -> 45
A11: Yellow Cards | B11: =IFERROR(INDIRECT("'" & SUBSTITUTE($B$1,"'","''") & "'!B20"), "") -> 0.13 | C11: =IFERROR(INDIRECT("'" & SUBSTITUTE($B$1,"'","''") & "'!C20"), "") -> 79 | D11: =IFERROR(INDIRECT("'" & SUBSTITUTE($D$1,"'","''") & "'!B20"), "") -> 0.3 | E11: =IFERROR(INDIRECT("'" & SUBSTITUTE($D$1,"'","''") & "'!C20"), "") -> 24 | F11: =IFERROR(INDIRECT("'" & SUBSTITUTE($F$1,"'","''") & "'!B20"), "") -> 0.16 | G11: =IFERROR(INDIRECT("'" & SUBSTITUTE($F$1,"'","''") & "'!C20"), "") -> 70 | H11: =IFERROR(INDIRECT("'" & SUBSTITUTE($H$1,"'","''") & "'!B20"), "") -> 0.26 | I11: =IFERROR(INDIRECT("'" & SUBSTITUTE($H$1,"'","''") & "'!C20"), "") -> 35 | J11: =IFERROR(INDIRECT("'" & SUBSTITUTE($J$1,"'","''") & "'!B20"), "") -> 0.26 | K11: =IFERROR(INDIRECT("'" & SUBSTITUTE($J$1,"'","''") & "'!C20"), "") -> 25 | L11: =IFERROR(INDIRECT("'" & SUBSTITUTE($L$1,"'","''") & "'!B20"), "") -> 0.15 | M11: =IFERROR(INDIRECT("'" & SUBSTITUTE($L$1,"'","''") & "'!C20"), "") -> 77 | N11: =IFERROR(INDIRECT("'" & SUBSTITUTE($N$1,"'","''") & "'!B20"), "") -> 0.36 | O11: =IFERROR(INDIRECT("'" & SUBSTITUTE($N$1,"'","''") & "'!C20"), "") -> 19 | P11: =IFERROR(INDIRECT("'" & SUBSTITUTE($P$1,"'","''") & "'!B20"), "") -> 0.07 | Q11: =IFERROR(INDIRECT("'" & SUBSTITUTE($P$1,"'","''") & "'!C20"), "") -> 86 | R11: =IFERROR(INDIRECT("'" & SUBSTITUTE($R$1,"'","''") & "'!B20"), "") -> 0.15 | S11: =IFERROR(INDIRECT("'" & SUBSTITUTE($R$1,"'","''") & "'!C20"), "") -> 68 | T11: =IFERROR(INDIRECT("'" & SUBSTITUTE($T$1,"'","''") & "'!B20"), "") -> 0.36 | U11: =IFERROR(INDIRECT("'" & SUBSTITUTE($T$1,"'","''") & "'!C20"), "") -> 20 | V11: =IFERROR(INDIRECT("'" & SUBSTITUTE($V$1,"'","''") & "'!B20"), "") -> 0.44 | W11: =IFERROR(INDIRECT("'" & SUBSTITUTE($V$1,"'","''") & "'!C20"), "") -> 7 | X11: =IFERROR(INDIRECT("'" & SUBSTITUTE($X$1,"'","''") & "'!B20"), "") -> 0.18 | Y11: =IFERROR(INDIRECT("'" & SUBSTITUTE($X$1,"'","''") & "'!C20"), "") -> 51
A12: Red Cards | B12: =IFERROR(INDIRECT("'" & SUBSTITUTE($B$1,"'","''") & "'!B23"), "") -> 0 | C12: =IFERROR(INDIRECT("'" & SUBSTITUTE($B$1,"'","''") & "'!C23"), "") -> 59 | D12: =IFERROR(INDIRECT("'" & SUBSTITUTE($D$1,"'","''") & "'!B23"), "") -> 0.03 | E12: =IFERROR(INDIRECT("'" & SUBSTITUTE($D$1,"'","''") & "'!C23"), "") -> 13 | F12: =IFERROR(INDIRECT("'" & SUBSTITUTE($F$1,"'","''") & "'!B23"), "") -> 0 | G12: =IFERROR(INDIRECT("'" & SUBSTITUTE($F$1,"'","''") & "'!C23"), "") -> 59 | H12: =IFERROR(INDIRECT("'" & SUBSTITUTE($H$1,"'","''") & "'!B23"), "") -> 0 | I12: =IFERROR(INDIRECT("'" & SUBSTITUTE($H$1,"'","''") & "'!C23"), "") -> 59 | J12: =IFERROR(INDIRECT("'" & SUBSTITUTE($J$1,"'","''") & "'!B23"), "") -> 0 | K12: =IFERROR(INDIRECT("'" & SUBSTITUTE($J$1,"'","''") & "'!C23"), "") -> 62 | L12: =IFERROR(INDIRECT("'" & SUBSTITUTE($L$1,"'","''") & "'!B23"), "") -> 0 | M12: =IFERROR(INDIRECT("'" & SUBSTITUTE($L$1,"'","''") & "'!C23"), "") -> 58 | N12: =IFERROR(INDIRECT("'" & SUBSTITUTE($N$1,"'","''") & "'!B23"), "") -> 0.03 | O12: =IFERROR(INDIRECT("'" & SUBSTITUTE($N$1,"'","''") & "'!C23"), "") -> 11 | P12: =IFERROR(INDIRECT("'" & SUBSTITUTE($P$1,"'","''") & "'!B23"), "") -> 0.04 | Q12: =IFERROR(INDIRECT("'" & SUBSTITUTE($P$1,"'","''") & "'!C23"), "") -> 7 | R12: =IFERROR(INDIRECT("'" & SUBSTITUTE($R$1,"'","''") & "'!B23"), "") -> 0 | S12: =IFERROR(INDIRECT("'" & SUBSTITUTE($R$1,"'","''") & "'!C23"), "") -> 55 | T12: =IFERROR(INDIRECT("'" & SUBSTITUTE($T$1,"'","''") & "'!B23"), "") -> 0 | U12: =IFERROR(INDIRECT("'" & SUBSTITUTE($T$1,"'","''") & "'!C23"), "") -> 55 | V12: =IFERROR(INDIRECT("'" & SUBSTITUTE($V$1,"'","''") & "'!B23"), "") -> 0 | W12: =IFERROR(INDIRECT("'" & SUBSTITUTE($V$1,"'","''") & "'!C23"), "") -> 58 | X12: =IFERROR(INDIRECT("'" & SUBSTITUTE($X$1,"'","''") & "'!B23"), "") -> 0 | Y12: =IFERROR(INDIRECT("'" & SUBSTITUTE($X$1,"'","''") & "'!C23"), "") -> 54
A13: xG: Expected Goals | B13: =IFERROR(INDIRECT("'" & SUBSTITUTE($B$1,"'","''") & "'!B26"), "") -> 0.19 | C13: =IFERROR(INDIRECT("'" & SUBSTITUTE($B$1,"'","''") & "'!C26"), "") -> 90 | D13: =IFERROR(INDIRECT("'" & SUBSTITUTE($D$1,"'","''") & "'!B26"), "") -> 0.08 | E13: =IFERROR(INDIRECT("'" & SUBSTITUTE($D$1,"'","''") & "'!C26"), "") -> 57 | F13: =IFERROR(INDIRECT("'" & SUBSTITUTE($F$1,"'","''") & "'!B26"), "") -> 0.08 | G13: =IFERROR(INDIRECT("'" & SUBSTITUTE($F$1,"'","''") & "'!C26"), "") -> 57 | H13: =IFERROR(INDIRECT("'" & SUBSTITUTE($H$1,"'","''") & "'!B26"), "") -> 0.01 | I13: =IFERROR(INDIRECT("'" & SUBSTITUTE($H$1,"'","''") & "'!C26"), "") -> 5 | J13: =IFERROR(INDIRECT("'" & SUBSTITUTE($J$1,"'","''") & "'!B26"), "") -> 0.07 | K13: =IFERROR(INDIRECT("'" & SUBSTITUTE($J$1,"'","''") & "'!C26"), "") -> 76 | L13: =IFERROR(INDIRECT("'" & SUBSTITUTE($L$1,"'","''") & "'!B26"), "") -> 0.03 | M13: =IFERROR(INDIRECT("'" & SUBSTITUTE($L$1,"'","''") & "'!C26"), "") -> 17 | N13: =IFERROR(INDIRECT("'" & SUBSTITUTE($N$1,"'","''") & "'!B26"), "") -> 0.14 | O13: =IFERROR(INDIRECT("'" & SUBSTITUTE($N$1,"'","''") & "'!C26"), "") -> 68 | P13: =IFERROR(INDIRECT("'" & SUBSTITUTE($P$1,"'","''") & "'!B26"), "") -> 0.09 | Q13: =IFERROR(INDIRECT("'" & SUBSTITUTE($P$1,"'","''") & "'!C26"), "") -> 46 | R13: =IFERROR(INDIRECT("'" & SUBSTITUTE($R$1,"'","''") & "'!B26"), "") -> 0.07 | S13: =IFERROR(INDIRECT("'" & SUBSTITUTE($R$1,"'","''") & "'!C26"), "") -> 34 | T13: =IFERROR(INDIRECT("'" & SUBSTITUTE($T$1,"'","''") & "'!B26"), "") -> 0.16 | U13: =IFERROR(INDIRECT("'" & SUBSTITUTE($T$1,"'","''") & "'!C26"), "") -> 81 | V13: =IFERROR(INDIRECT("'" & SUBSTITUTE($V$1,"'","''") & "'!B26"), "") -> 0.03 | W13: =IFERROR(INDIRECT("'" & SUBSTITUTE($V$1,"'","''") & "'!C26"), "") -> 18 | X13: =IFERROR(INDIRECT("'" & SUBSTITUTE($X$1,"'","''") & "'!B26"), "") -> 0.1 | Y13: =IFERROR(INDIRECT("'" & SUBSTITUTE($X$1,"'","''") & "'!C26"), "") -> 56
A14: npxG: Non-Penalty xG | B14: =IFERROR(INDIRECT("'" & SUBSTITUTE($B$1,"'","''") & "'!B29"), "") -> 0.19 | C14: =IFERROR(INDIRECT("'" & SUBSTITUTE($B$1,"'","''") & "'!C29"), "") -> 92 | D14: =IFERROR(INDIRECT("'" & SUBSTITUTE($D$1,"'","''") & "'!B29"), "") -> 0.08 | E14: =IFERROR(INDIRECT("'" & SUBSTITUTE($D$1,"'","''") & "'!C29"), "") -> 61 | F14: =IFERROR(INDIRECT("'" & SUBSTITUTE($F$1,"'","''") & "'!B29"), "") -> 0.08 | G14: =IFERROR(INDIRECT("'" & SUBSTITUTE($F$1,"'","''") & "'!C29"), "") -> 61 | H14: =IFERROR(INDIRECT("'" & SUBSTITUTE($H$1,"'","''") & "'!B29"), "") -> 0.01 | I14: =IFERROR(INDIRECT("'" & SUBSTITUTE($H$1,"'","''") & "'!C29"), "") -> 5 | J14: =IFERROR(INDIRECT("'" & SUBSTITUTE($J$1,"'","''") & "'!B29"), "") -> 0.07 | K14: =IFERROR(INDIRECT("'" & SUBSTITUTE($J$1,"'","''") & "'!C29"), "") -> 77 | L14: =IFERROR(INDIRECT("'" & SUBSTITUTE($L$1,"'","''") & "'!B29"), "") -> 0.03 | M14: =IFERROR(INDIRECT("'" & SUBSTITUTE($L$1,"'","''") & "'!C29"), "") -> 18 | N14: =IFERROR(INDIRECT("'" & SUBSTITUTE($N$1,"'","''") & "'!B29"), "") -> 0.14 | O14: =IFERROR(INDIRECT("'" & SUBSTITUTE($N$1,"'","''") & "'!C29"), "") -> 71 | P14: =IFERROR(INDIRECT("'" & SUBSTITUTE($P$1,"'","''") & "'!B29"), "") -> 0.09 | Q14: =IFERROR(INDIRECT("'" & SUBSTITUTE($P$1,"'","''") & "'!C29"), "") -> 49 | R14: =IFERROR(INDIRECT("'" & SUBSTITUTE($R$1,"'","''") & "'!B29"), "") -> 0.07 | S14: =IFERROR(INDIRECT("'" & SUBSTITUTE($R$1,"'","''") & "'!C29"), "") -> 37 | T14: =IFERROR(INDIRECT("'" & SUBSTITUTE($T$1,"'","''") & "'!B29"), "") -> 0.08 | U14: =IFERROR(INDIRECT("'" & SUBSTITUTE($T$1,"'","''") & "'!C29"), "") -> 46 | V14: =IFERROR(INDIRECT("'" & SUBSTITUTE($V$1,"'","''") & "'!B29"), "") -> 0.03 | W14: =IFERROR(INDIRECT("'" & SUBSTITUTE($V$1,"'","''") & "'!C29"), "") -> 18 | X14: =IFERROR(INDIRECT("'" & SUBSTITUTE($X$1,"'","''") & "'!B29"), "") -> 0.1 | Y14: =IFERROR(INDIRECT("'" & SUBSTITUTE($X$1,"'","''") & "'!C29"), "") -> 62
A15: xAG: Exp. Assisted Goals | B15: =IFERROR(INDIRECT("'" & SUBSTITUTE($B$1,"'","''") & "'!B32"), "") -> 0.13 | C15: =IFERROR(INDIRECT("'" & SUBSTITUTE($B$1,"'","''") & "'!C32"), "") -> 77 | D15: =IFERROR(INDIRECT("'" & SUBSTITUTE($D$1,"'","''") & "'!B32"), "") -> 0.04 | E15: =IFERROR(INDIRECT("'" & SUBSTITUTE($D$1,"'","''") & "'!C32"), "") -> 16 | F15: =IFERROR(INDIRECT("'" & SUBSTITUTE($F$1,"'","''") & "'!B32"), "") -> 0.2 | G15: =IFERROR(INDIRECT("'" & SUBSTITUTE($F$1,"'","''") & "'!C32"), "") -> 91 | H15: =IFERROR(INDIRECT("'" & SUBSTITUTE($H$1,"'","''") & "'!B32"), "") -> 0.03 | I15: =IFERROR(INDIRECT("'" & SUBSTITUTE($H$1,"'","''") & "'!C32"), "") -> 7 | J15: =IFERROR(INDIRECT("'" & SUBSTITUTE($J$1,"'","''") & "'!B32"), "") -> 0.03 | K15: =IFERROR(INDIRECT("'" & SUBSTITUTE($J$1,"'","''") & "'!C32"), "") -> 63 | L15: =IFERROR(INDIRECT("'" & SUBSTITUTE($L$1,"'","''") & "'!B32"), "") -> 0.03 | M15: =IFERROR(INDIRECT("'" & SUBSTITUTE($L$1,"'","''") & "'!C32"), "") -> 11 | N15: =IFERROR(INDIRECT("'" & SUBSTITUTE($N$1,"'","''") & "'!B32"), "") -> 0.05 | O15: =IFERROR(INDIRECT("'" & SUBSTITUTE($N$1,"'","''") & "'!C32"), "") -> 23 | P15: =IFERROR(INDIRECT("'" & SUBSTITUTE($P$1,"'","''") & "'!B32"), "") -> 0.08 | Q15: =IFERROR(INDIRECT("'" & SUBSTITUTE($P$1,"'","''") & "'!C32"), "") -> 41 | R15: =IFERROR(INDIRECT("'" & SUBSTITUTE($R$1,"'","''") & "'!B32"), "") -> 0.13 | S15: =IFERROR(INDIRECT("'" & SUBSTITUTE($R$1,"'","''") & "'!C32"), "") -> 70 | T15: =IFERROR(INDIRECT("'" & SUBSTITUTE($T$1,"'","''") & "'!B32"), "") -> 0.05 | U15: =IFERROR(INDIRECT("'" & SUBSTITUTE($T$1,"'","''") & "'!C32"), "") -> 23 | V15: =IFERROR(INDIRECT("'" & SUBSTITUTE($V$1,"'","''") & "'!B32"), "") -> 0.04 | W15: =IFERROR(INDIRECT("'" & SUBSTITUTE($V$1,"'","''") & "'!C32"), "") -> 20 | X15: =IFERROR(INDIRECT("'" & SUBSTITUTE($X$1,"'","''") & "'!B32"), "") -> 0.05 | Y15: =IFERROR(INDIRECT("'" & SUBSTITUTE($X$1,"'","''") & "'!C32"), "") -> 25
A16: npxG + xAG | B16: =IFERROR(INDIRECT("'" & SUBSTITUTE($B$1,"'","''") & "'!B35"), "") -> 0.32 | C16: =IFERROR(INDIRECT("'" & SUBSTITUTE($B$1,"'","''") & "'!C35"), "") -> 89 | D16: =IFERROR(INDIRECT("'" & SUBSTITUTE($D$1,"'","''") & "'!B35"), "") -> 0.12 | E16: =IFERROR(INDIRECT("'" & SUBSTITUTE($D$1,"'","''") & "'!C35"), "") -> 35 | F16: =IFERROR(INDIRECT("'" & SUBSTITUTE($F$1,"'","''") & "'!B35"), "") -> 0.28 | G16: =IFERROR(INDIRECT("'" & SUBSTITUTE($F$1,"'","''") & "'!C35"), "") -> 85 | H16: =IFERROR(INDIRECT("'" & SUBSTITUTE($H$1,"'","''") & "'!B35"), "") -> 0.04 | I16: =IFERROR(INDIRECT("'" & SUBSTITUTE($H$1,"'","''") & "'!C35"), "") -> 2 | J16: =IFERROR(INDIRECT("'" & SUBSTITUTE($J$1,"'","''") & "'!B35"), "") -> 0.1 | K16: =IFERROR(INDIRECT("'" & SUBSTITUTE($J$1,"'","''") & "'!C35"), "") -> 73 | L16: =IFERROR(INDIRECT("'" & SUBSTITUTE($L$1,"'","''") & "'!B35"), "") -> 0.07 | M16: =IFERROR(INDIRECT("'" & SUBSTITUTE($L$1,"'","''") & "'!C35"), "") -> 7 | N16: =IFERROR(INDIRECT("'" & SUBSTITUTE($N$1,"'","''") & "'!B35"), "") -> 0.19 | O16: =IFERROR(INDIRECT("'" & SUBSTITUTE($N$1,"'","''") & "'!C35"), "") -> 44 | P16: =IFERROR(INDIRECT("'" & SUBSTITUTE($P$1,"'","''") & "'!B35"), "") -> 0.17 | Q16: =IFERROR(INDIRECT("'" & SUBSTITUTE($P$1,"'","''") & "'!C35"), "") -> 43 | R16: =IFERROR(INDIRECT("'" & SUBSTITUTE($R$1,"'","''") & "'!B35"), "") -> 0.2 | S16: =IFERROR(INDIRECT("'" & SUBSTITUTE($R$1,"'","''") & "'!C35"), "") -> 51 | T16: =IFERROR(INDIRECT("'" & SUBSTITUTE($T$1,"'","''") & "'!B35"), "") -> 0.13 | U16: =IFERROR(INDIRECT("'" & SUBSTITUTE($T$1,"'","''") & "'!C35"), "") -> 30 | V16: =IFERROR(INDIRECT("'" & SUBSTITUTE($V$1,"'","''") & "'!B35"), "") -> 0.08 | W16: =IFERROR(INDIRECT("'" & SUBSTITUTE($V$1,"'","''") & "'!C35"), "") -> 14 | X16: =IFERROR(INDIRECT("'" & SUBSTITUTE($X$1,"'","''") & "'!B35"), "") -> 0.15 | Y16: =IFERROR(INDIRECT("'" & SUBSTITUTE($X$1,"'","''") & "'!C35"), "") -> 46
A17: Progressive Carries | B17: =IFERROR(INDIRECT("'" & SUBSTITUTE($B$1,"'","''") & "'!B39"), "") -> 0.68 | C17: =IFERROR(INDIRECT("'" & SUBSTITUTE($B$1,"'","''") & "'!C39"), "") -> 16 | D17: =IFERROR(INDIRECT("'" & SUBSTITUTE($D$1,"'","''") & "'!B39"), "") -> 1.57 | E17: =IFERROR(INDIRECT("'" & SUBSTITUTE($D$1,"'","''") & "'!C39"), "") -> 70 | F17: =IFERROR(INDIRECT("'" & SUBSTITUTE($F$1,"'","''") & "'!B39"), "") -> 3.03 | G17: =IFERROR(INDIRECT("'" & SUBSTITUTE($F$1,"'","''") & "'!C39"), "") -> 97 | H17: =IFERROR(INDIRECT("'" & SUBSTITUTE($H$1,"'","''") & "'!B39"), "") -> 0.54 | I17: =IFERROR(INDIRECT("'" & SUBSTITUTE($H$1,"'","''") & "'!C39"), "") -> 8 | J17: =IFERROR(INDIRECT("'" & SUBSTITUTE($J$1,"'","''") & "'!B39"), "") -> 0.69 | K17: =IFERROR(INDIRECT("'" & SUBSTITUTE($J$1,"'","''") & "'!C39"), "") -> 59 | L17: =IFERROR(INDIRECT("'" & SUBSTITUTE($L$1,"'","''") & "'!B39"), "") -> 1.55 | M17: =IFERROR(INDIRECT("'" & SUBSTITUTE($L$1,"'","''") & "'!C39"), "") -> 54 | N17: =IFERROR(INDIRECT("'" & SUBSTITUTE($N$1,"'","''") & "'!B39"), "") -> 0.97 | O17: =IFERROR(INDIRECT("'" & SUBSTITUTE($N$1,"'","''") & "'!C39"), "") -> 31 | P17: =IFERROR(INDIRECT("'" & SUBSTITUTE($P$1,"'","''") & "'!B39"), "") -> 2.15 | Q17: =IFERROR(INDIRECT("'" & SUBSTITUTE($P$1,"'","''") & "'!C39"), "") -> 72 | R17: =IFERROR(INDIRECT("'" & SUBSTITUTE($R$1,"'","''") & "'!B39"), "") -> 1.16 | S17: =IFERROR(INDIRECT("'" & SUBSTITUTE($R$1,"'","''") & "'!C39"), "") -> 48 | T17: =IFERROR(INDIRECT("'" & SUBSTITUTE($T$1,"'","''") & "'!B39"), "") -> 0.83 | U17: =IFERROR(INDIRECT("'" & SUBSTITUTE($T$1,"'","''") & "'!C39"), "") -> 27 | V17: =IFERROR(INDIRECT("'" & SUBSTITUTE($V$1,"'","''") & "'!B39"), "") -> 0.99 | W17: =IFERROR(INDIRECT("'" & SUBSTITUTE($V$1,"'","''") & "'!C39"), "") -> 34 | X17: =IFERROR(INDIRECT("'" & SUBSTITUTE($X$1,"'","''") & "'!B39"), "") -> 0.42 | Y17: =IFERROR(INDIRECT("'" & SUBSTITUTE($X$1,"'","''") & "'!C39"), "") -> 6
A18: Progressive Passes | B18: =IFERROR(INDIRECT("'" & SUBSTITUTE($B$1,"'","''") & "'!B42"), "") -> 1.2 | C18: =IFERROR(INDIRECT("'" & SUBSTITUTE($B$1,"'","''") & "'!C42"), "") -> 1 | D18: =IFERROR(INDIRECT("'" & SUBSTITUTE($D$1,"'","''") & "'!B42"), "") -> 5.63 | E18: =IFERROR(INDIRECT("'" & SUBSTITUTE($D$1,"'","''") & "'!C42"), "") -> 69 | F18: =IFERROR(INDIRECT("'" & SUBSTITUTE($F$1,"'","''") & "'!B42"), "") -> 3.34 | G18: =IFERROR(INDIRECT("'" & SUBSTITUTE($F$1,"'","''") & "'!C42"), "") -> 17 | H18: =IFERROR(INDIRECT("'" & SUBSTITUTE($H$1,"'","''") & "'!B42"), "") -> 4.03 | I18: =IFERROR(INDIRECT("'" & SUBSTITUTE($H$1,"'","''") & "'!C42"), "") -> 34 | J18: =IFERROR(INDIRECT("'" & SUBSTITUTE($J$1,"'","''") & "'!B42"), "") -> 4.97 | K18: =IFERROR(INDIRECT("'" & SUBSTITUTE($J$1,"'","''") & "'!C42"), "") -> 86 | L18: =IFERROR(INDIRECT("'" & SUBSTITUTE($L$1,"'","''") & "'!B42"), "") -> 5.97 | M18: =IFERROR(INDIRECT("'" & SUBSTITUTE($L$1,"'","''") & "'!C42"), "") -> 79 | N18: =IFERROR(INDIRECT("'" & SUBSTITUTE($N$1,"'","''") & "'!B42"), "") -> 2.3 | O18: =IFERROR(INDIRECT("'" & SUBSTITUTE($N$1,"'","''") & "'!C42"), "") -> 5 | P18: =IFERROR(INDIRECT("'" & SUBSTITUTE($P$1,"'","''") & "'!B42"), "") -> 3.06 | Q18: =IFERROR(INDIRECT("'" & SUBSTITUTE($P$1,"'","''") & "'!C42"), "") -> 21 | R18: =IFERROR(INDIRECT("'" & SUBSTITUTE($R$1,"'","''") & "'!B42"), "") -> 6.67 | S18: =IFERROR(INDIRECT("'" & SUBSTITUTE($R$1,"'","''") & "'!C42"), "") -> 82 | T18: =IFERROR(INDIRECT("'" & SUBSTITUTE($T$1,"'","''") & "'!B42"), "") -> 6.5 | U18: =IFERROR(INDIRECT("'" & SUBSTITUTE($T$1,"'","''") & "'!C42"), "") -> 80 | V18: =IFERROR(INDIRECT("'" & SUBSTITUTE($V$1,"'","''") & "'!B42"), "") -> 3.19 | W18: =IFERROR(INDIRECT("'" & SUBSTITUTE($V$1,"'","''") & "'!C42"), "") -> 18 | X18: =IFERROR(INDIRECT("'" & SUBSTITUTE($X$1,"'","''") & "'!B42"), "") -> 2.95 | Y18: =IFERROR(INDIRECT("'" & SUBSTITUTE($X$1,"'","''") & "'!C42"), "") -> 20
A19: Progressive Passes Rec | B19: =IFERROR(INDIRECT("'" & SUBSTITUTE($B$1,"'","''") & "'!B45"), "") -> 2.96 | C19: =IFERROR(INDIRECT("'" & SUBSTITUTE($B$1,"'","''") & "'!C45"), "") -> 79 | D19: =IFERROR(INDIRECT("'" & SUBSTITUTE($D$1,"'","''") & "'!B45"), "") -> 2.27 | E19: =IFERROR(INDIRECT("'" & SUBSTITUTE($D$1,"'","''") & "'!C45"), "") -> 64 | F19: =IFERROR(INDIRECT("'" & SUBSTITUTE($F$1,"'","''") & "'!B45"), "") -> 4.23 | G19: =IFERROR(INDIRECT("'" & SUBSTITUTE($F$1,"'","''") & "'!C45"), "") -> 89 | H19: =IFERROR(INDIRECT("'" & SUBSTITUTE($H$1,"'","''") & "'!B45"), "") -> 0.45 | I19: =IFERROR(INDIRECT("'" & SUBSTITUTE($H$1,"'","''") & "'!C45"), "") -> 3 | J19: =IFERROR(INDIRECT("'" & SUBSTITUTE($J$1,"'","''") & "'!B45"), "") -> 0.37 | K19: =IFERROR(INDIRECT("'" & SUBSTITUTE($J$1,"'","''") & "'!C45"), "") -> 63 | L19: =IFERROR(INDIRECT("'" & SUBSTITUTE($L$1,"'","''") & "'!B45"), "") -> 1.25 | M19: =IFERROR(INDIRECT("'" & SUBSTITUTE($L$1,"'","''") & "'!C45"), "") -> 25 | N19: =IFERROR(INDIRECT("'" & SUBSTITUTE($N$1,"'","''") & "'!B45"), "") -> 1.49 | O19: =IFERROR(INDIRECT("'" & SUBSTITUTE($N$1,"'","''") & "'!C45"), "") -> 29 | P19: =IFERROR(INDIRECT("'" & SUBSTITUTE($P$1,"'","''") & "'!B45"), "") -> 4.71 | Q19: =IFERROR(INDIRECT("'" & SUBSTITUTE($P$1,"'","''") & "'!C45"), "") -> 77 | R19: =IFERROR(INDIRECT("'" & SUBSTITUTE($R$1,"'","''") & "'!B45"), "") -> 1.62 | S19: =IFERROR(INDIRECT("'" & SUBSTITUTE($R$1,"'","''") & "'!C45"), "") -> 43 | T19: =IFERROR(INDIRECT("'" & SUBSTITUTE($T$1,"'","''") & "'!B45"), "") -> 0.54 | U19: =IFERROR(INDIRECT("'" & SUBSTITUTE($T$1,"'","''") & "'!C45"), "") -> 13 | V19: =IFERROR(INDIRECT("'" & SUBSTITUTE($V$1,"'","''") & "'!B45"), "") -> 1.65 | W19: =IFERROR(INDIRECT("'" & SUBSTITUTE($V$1,"'","''") & "'!C45"), "") -> 34 | X19: =IFERROR(INDIRECT("'" & SUBSTITUTE($X$1,"'","''") & "'!B45"), "") -> 2.08 | Y19: =IFERROR(INDIRECT("'" & SUBSTITUTE($X$1,"'","''") & "'!C45"), "") -> 45
A20: Shots Total | B20: =IFERROR(INDIRECT("'" & SUBSTITUTE($B$1,"'","''") & "'!B53"), "") -> 1.59 | C20: =IFERROR(INDIRECT("'" & SUBSTITUTE($B$1,"'","''") & "'!C53"), "") -> 84 | D20: =IFERROR(INDIRECT("'" & SUBSTITUTE($D$1,"'","''") & "'!B53"), "") -> 1.06 | E20: =IFERROR(INDIRECT("'" & SUBSTITUTE($D$1,"'","''") & "'!C53"), "") -> 54 | F20: =IFERROR(INDIRECT("'" & SUBSTITUTE($F$1,"'","''") & "'!B53"), "") -> 1.46 | G20: =IFERROR(INDIRECT("'" & SUBSTITUTE($F$1,"'","''") & "'!C53"), "") -> 77 | H20: =IFERROR(INDIRECT("'" & SUBSTITUTE($H$1,"'","''") & "'!B53"), "") -> 0.32 | I20: =IFERROR(INDIRECT("'" & SUBSTITUTE($H$1,"'","''") & "'!C53"), "") -> 5 | J20: =IFERROR(INDIRECT("'" & SUBSTITUTE($J$1,"'","''") & "'!B53"), "") -> 0.69 | K20: =IFERROR(INDIRECT("'" & SUBSTITUTE($J$1,"'","''") & "'!C53"), "") -> 76 | L20: =IFERROR(INDIRECT("'" & SUBSTITUTE($L$1,"'","''") & "'!B53"), "") -> 1.03 | M20: =IFERROR(INDIRECT("'" & SUBSTITUTE($L$1,"'","''") & "'!C53"), "") -> 36 | N20: =IFERROR(INDIRECT("'" & SUBSTITUTE($N$1,"'","''") & "'!B53"), "") -> 1.46 | O20: =IFERROR(INDIRECT("'" & SUBSTITUTE($N$1,"'","''") & "'!C53"), "") -> 69 | P20: =IFERROR(INDIRECT("'" & SUBSTITUTE($P$1,"'","''") & "'!B53"), "") -> 1.02 | Q20: =IFERROR(INDIRECT("'" & SUBSTITUTE($P$1,"'","''") & "'!C53"), "") -> 46 | R20: =IFERROR(INDIRECT("'" & SUBSTITUTE($R$1,"'","''") & "'!B53"), "") -> 0.81 | S20: =IFERROR(INDIRECT("'" & SUBSTITUTE($R$1,"'","''") & "'!C53"), "") -> 30 | T20: =IFERROR(INDIRECT("'" & SUBSTITUTE($T$1,"'","''") & "'!B53"), "") -> 1.88 | U20: =IFERROR(INDIRECT("'" & SUBSTITUTE($T$1,"'","''") & "'!C53"), "") -> 86 | V20: =IFERROR(INDIRECT("'" & SUBSTITUTE($V$1,"'","''") & "'!B53"), "") -> 1.21 | W20: =IFERROR(INDIRECT("'" & SUBSTITUTE($V$1,"'","''") & "'!C53"), "") -> 47 | X20: =IFERROR(INDIRECT("'" & SUBSTITUTE($X$1,"'","''") & "'!B53"), "") -> 1.06 | Y20: =IFERROR(INDIRECT("'" & SUBSTITUTE($X$1,"'","''") & "'!C53"), "") -> 43
A21: Shots on Target | B21: =IFERROR(INDIRECT("'" & SUBSTITUTE($B$1,"'","''") & "'!B56"), "") -> 0.52 | C21: =IFERROR(INDIRECT("'" & SUBSTITUTE($B$1,"'","''") & "'!C56"), "") -> 82 | D21: =IFERROR(INDIRECT("'" & SUBSTITUTE($D$1,"'","''") & "'!B56"), "") -> 0.18 | E21: =IFERROR(INDIRECT("'" & SUBSTITUTE($D$1,"'","''") & "'!C56"), "") -> 34 | F21: =IFERROR(INDIRECT("'" & SUBSTITUTE($F$1,"'","''") & "'!B56"), "") -> 0.31 | G21: =IFERROR(INDIRECT("'" & SUBSTITUTE($F$1,"'","''") & "'!C56"), "") -> 58 | H21: =IFERROR(INDIRECT("'" & SUBSTITUTE($H$1,"'","''") & "'!B56"), "") -> 0 | I21: =IFERROR(INDIRECT("'" & SUBSTITUTE($H$1,"'","''") & "'!C56"), "") -> 2 | J21: =IFERROR(INDIRECT("'" & SUBSTITUTE($J$1,"'","''") & "'!B56"), "") -> 0.26 | K21: =IFERROR(INDIRECT("'" & SUBSTITUTE($J$1,"'","''") & "'!C56"), "") -> 89 | L21: =IFERROR(INDIRECT("'" & SUBSTITUTE($L$1,"'","''") & "'!B56"), "") -> 0.22 | M21: =IFERROR(INDIRECT("'" & SUBSTITUTE($L$1,"'","''") & "'!C56"), "") -> 30 | N21: =IFERROR(INDIRECT("'" & SUBSTITUTE($N$1,"'","''") & "'!B56"), "") -> 0.55 | O21: =IFERROR(INDIRECT("'" & SUBSTITUTE($N$1,"'","''") & "'!C56"), "") -> 80 | P21: =IFERROR(INDIRECT("'" & SUBSTITUTE($P$1,"'","''") & "'!B56"), "") -> 0.33 | Q21: =IFERROR(INDIRECT("'" & SUBSTITUTE($P$1,"'","''") & "'!C56"), "") -> 50 | R21: =IFERROR(INDIRECT("'" & SUBSTITUTE($R$1,"'","''") & "'!B56"), "") -> 0.15 | S21: =IFERROR(INDIRECT("'" & SUBSTITUTE($R$1,"'","''") & "'!C56"), "") -> 23 | T21: =IFERROR(INDIRECT("'" & SUBSTITUTE($T$1,"'","''") & "'!B56"), "") -> 0.39 | U21: =IFERROR(INDIRECT("'" & SUBSTITUTE($T$1,"'","''") & "'!C56"), "") -> 60 | V21: =IFERROR(INDIRECT("'" & SUBSTITUTE($V$1,"'","''") & "'!B56"), "") -> 0.11 | W21: =IFERROR(INDIRECT("'" & SUBSTITUTE($V$1,"'","''") & "'!C56"), "") -> 11 | X21: =IFERROR(INDIRECT("'" & SUBSTITUTE($X$1,"'","''") & "'!B56"), "") -> 0.46 | Y21: =IFERROR(INDIRECT("'" & SUBSTITUTE($X$1,"'","''") & "'!C56"), "") -> 66
A22: Shots on Target % | B22: =IFERROR(INDIRECT("'" & SUBSTITUTE($B$1,"'","''") & "'!B59"), "") -> 0.327 | C22: =IFERROR(INDIRECT("'" & SUBSTITUTE($B$1,"'","''") & "'!C59"), "") -> 65 | D22: =IFERROR(INDIRECT("'" & SUBSTITUTE($D$1,"'","''") & "'!B59"), "") -> 0.171 | E22: =IFERROR(INDIRECT("'" & SUBSTITUTE($D$1,"'","''") & "'!C59"), "") -> 15 | F22: =IFERROR(INDIRECT("'" & SUBSTITUTE($F$1,"'","''") & "'!B59"), "") -> 0.214 | G22: =IFERROR(INDIRECT("'" & SUBSTITUTE($F$1,"'","''") & "'!C59"), "") -> 27 | H22: =IFERROR(INDIRECT("'" & SUBSTITUTE($H$1,"'","''") & "'!B59"), "") -> 0 | I22: =IFERROR(INDIRECT("'" & SUBSTITUTE($H$1,"'","''") & "'!C59"), "") -> 2 | J22: =IFERROR(INDIRECT("'" & SUBSTITUTE($J$1,"'","''") & "'!B59"), "") -> 0.375 | K22: =IFERROR(INDIRECT("'" & SUBSTITUTE($J$1,"'","''") & "'!C59"), "") -> 76 | L22: =IFERROR(INDIRECT("'" & SUBSTITUTE($L$1,"'","''") & "'!B59"), "") -> 0.214 | M22: =IFERROR(INDIRECT("'" & SUBSTITUTE($L$1,"'","''") & "'!C59"), "") -> 20 | N22: =IFERROR(INDIRECT("'" & SUBSTITUTE($N$1,"'","''") & "'!B59"), "") -> 0.375 | O22: =IFERROR(INDIRECT("'" & SUBSTITUTE($N$1,"'","''") & "'!C59"), "") -> 81 | P22: =IFERROR(INDIRECT("'" & SUBSTITUTE($P$1,"'","''") & "'!B59"), "") -> 0.321 | Q22: =IFERROR(INDIRECT("'" & SUBSTITUTE($P$1,"'","''") & "'!C59"), "") -> 55 | R22: =IFERROR(INDIRECT("'" & SUBSTITUTE($R$1,"'","''") & "'!B59"), "") -> 0.188 | S22: =IFERROR(INDIRECT("'" & SUBSTITUTE($R$1,"'","''") & "'!C59"), "") -> 18 | T22: =IFERROR(INDIRECT("'" & SUBSTITUTE($T$1,"'","''") & "'!B59"), "") -> 0.206 | U22: =IFERROR(INDIRECT("'" & SUBSTITUTE($T$1,"'","''") & "'!C59"), "") -> 23 | V22: =IFERROR(INDIRECT("'" & SUBSTITUTE($V$1,"'","''") & "'!B59"), "") -> 0.091 | W22: =IFERROR(INDIRECT("'" & SUBSTITUTE($V$1,"'","''") & "'!C59"), "") -> 5 | X22: =IFERROR(INDIRECT("'" & SUBSTITUTE($X$1,"'","''") & "'!B59"), "") -> 0.435 | Y22: =IFERROR(INDIRECT("'" & SUBSTITUTE($X$1,"'","''") & "'!C59"), "") -> 90
A23: Goals/Shot | B23: =IFERROR(INDIRECT("'" & SUBSTITUTE($B$1,"'","''") & "'!B62"), "") -> 0.08 | C23: =IFERROR(INDIRECT("'" & SUBSTITUTE($B$1,"'","''") & "'!C62"), "") -> 56 | D23: =IFERROR(INDIRECT("'" & SUBSTITUTE($D$1,"'","''") & "'!B62"), "") -> 0.06 | E23: =IFERROR(INDIRECT("'" & SUBSTITUTE($D$1,"'","''") & "'!C62"), "") -> 43 | F23: =IFERROR(INDIRECT("'" & SUBSTITUTE($F$1,"'","''") & "'!B62"), "") -> 0.04 | G23: =IFERROR(INDIRECT("'" & SUBSTITUTE($F$1,"'","''") & "'!C62"), "") -> 31 | H23: =IFERROR(INDIRECT("'" & SUBSTITUTE($H$1,"'","''") & "'!B62"), "") -> 0 | I23: =IFERROR(INDIRECT("'" & SUBSTITUTE($H$1,"'","''") & "'!C62"), "") -> 11 | J23: =IFERROR(INDIRECT("'" & SUBSTITUTE($J$1,"'","''") & "'!B62"), "") -> 0.13 | K23: =IFERROR(INDIRECT("'" & SUBSTITUTE($J$1,"'","''") & "'!C62"), "") -> 74 | L23: =IFERROR(INDIRECT("'" & SUBSTITUTE($L$1,"'","''") & "'!B62"), "") -> 0 | M23: =IFERROR(INDIRECT("'" & SUBSTITUTE($L$1,"'","''") & "'!C62"), "") -> 14 | N23: =IFERROR(INDIRECT("'" & SUBSTITUTE($N$1,"'","''") & "'!B62"), "") -> 0.08 | O23: =IFERROR(INDIRECT("'" & SUBSTITUTE($N$1,"'","''") & "'!C62"), "") -> 60 | P23: =IFERROR(INDIRECT("'" & SUBSTITUTE($P$1,"'","''") & "'!B62"), "") -> 0.04 | Q23: =IFERROR(INDIRECT("'" & SUBSTITUTE($P$1,"'","''") & "'!C62"), "") -> 42 | R23: =IFERROR(INDIRECT("'" & SUBSTITUTE($R$1,"'","''") & "'!B62"), "") -> 0 | S23: =IFERROR(INDIRECT("'" & SUBSTITUTE($R$1,"'","''") & "'!C62"), "") -> 16 | T23: =IFERROR(INDIRECT("'" & SUBSTITUTE($T$1,"'","''") & "'!B62"), "") -> 0.05 | U23: =IFERROR(INDIRECT("'" & SUBSTITUTE($T$1,"'","''") & "'!C62"), "") -> 47 | V23: =IFERROR(INDIRECT("'" & SUBSTITUTE($V$1,"'","''") & "'!B62"), "") -> 0 | W23: =IFERROR(INDIRECT("'" & SUBSTITUTE($V$1,"'","''") & "'!C62"), "") -> 14 | X23: =IFERROR(INDIRECT("'" & SUBSTITUTE($X$1,"'","''") & "'!B62"), "") -> 0.09 | Y23: =IFERROR(INDIRECT("'" & SUBSTITUTE($X$1,"'","''") & "'!C62"), "") -> 68
A24: Goals/Shot on Target | B24: =IFERROR(INDIRECT("'" & SUBSTITUTE($B$1,"'","''") & "'!B65"), "") -> 0.25 | C24: =IFERROR(INDIRECT("'" & SUBSTITUTE($B$1,"'","''") & "'!C65"), "") -> 49 | D24: =IFERROR(INDIRECT("'" & SUBSTITUTE($D$1,"'","''") & "'!B65"), "") -> 0.33 | E24: =IFERROR(INDIRECT("'" & SUBSTITUTE($D$1,"'","''") & "'!C65"), "") -> 69 | F24: =IFERROR(INDIRECT("'" & SUBSTITUTE($F$1,"'","''") & "'!B65"), "") -> 0.17 | G24: =IFERROR(INDIRECT("'" & SUBSTITUTE($F$1,"'","''") & "'!C65"), "") -> 30 | H24: =IFERROR(INDIRECT("'" & SUBSTITUTE($H$1,"'","''") & "'!B65"), "") -> 0 | I24: =IFERROR(INDIRECT("'" & SUBSTITUTE($H$1,"'","''") & "'!C65"), "") -> 0 | J24: =IFERROR(INDIRECT("'" & SUBSTITUTE($J$1,"'","''") & "'!B65"), "") -> 0.33 | K24: =IFERROR(INDIRECT("'" & SUBSTITUTE($J$1,"'","''") & "'!C65"), "") -> 57 | L24: =IFERROR(INDIRECT("'" & SUBSTITUTE($L$1,"'","''") & "'!B65"), "") -> 0 | M24: =IFERROR(INDIRECT("'" & SUBSTITUTE($L$1,"'","''") & "'!C65"), "") -> 14 | N24: =IFERROR(INDIRECT("'" & SUBSTITUTE($N$1,"'","''") & "'!B65"), "") -> 0.22 | O24: =IFERROR(INDIRECT("'" & SUBSTITUTE($N$1,"'","''") & "'!C65"), "") -> 45 | P24: =IFERROR(INDIRECT("'" & SUBSTITUTE($P$1,"'","''") & "'!B65"), "") -> 0.11 | Q24: =IFERROR(INDIRECT("'" & SUBSTITUTE($P$1,"'","''") & "'!C65"), "") -> 35 | R24: =IFERROR(INDIRECT("'" & SUBSTITUTE($R$1,"'","''") & "'!B65"), "") -> 0 | S24: =IFERROR(INDIRECT("'" & SUBSTITUTE($R$1,"'","''") & "'!C65"), "") -> 16 | T24: =IFERROR(INDIRECT("'" & SUBSTITUTE($T$1,"'","''") & "'!B65"), "") -> 0.23 | U24: =IFERROR(INDIRECT("'" & SUBSTITUTE($T$1,"'","''") & "'!C65"), "") -> 50 | V24: =IFERROR(INDIRECT("'" & SUBSTITUTE($V$1,"'","''") & "'!B65"), "") -> 0 | W24: =IFERROR(INDIRECT("'" & SUBSTITUTE($V$1,"'","''") & "'!C65"), "") -> 14 | X24: =IFERROR(INDIRECT("'" & SUBSTITUTE($X$1,"'","''") & "'!B65"), "") -> 0.2 | Y24: =IFERROR(INDIRECT("'" & SUBSTITUTE($X$1,"'","''") & "'!C65"), "") -> 48
A25: Average Shot Distance | B25: =IFERROR(INDIRECT("'" & SUBSTITUTE($B$1,"'","''") & "'!B68"), "") -> 14.7 | C25: =IFERROR(INDIRECT("'" & SUBSTITUTE($B$1,"'","''") & "'!C68"), "") -> 90 | D25: =IFERROR(INDIRECT("'" & SUBSTITUTE($D$1,"'","''") & "'!B68"), "") -> 18.8 | E25: =IFERROR(INDIRECT("'" & SUBSTITUTE($D$1,"'","''") & "'!C68"), "") -> 64 | F25: =IFERROR(INDIRECT("'" & SUBSTITUTE($F$1,"'","''") & "'!B68"), "") -> 22 | G25: =IFERROR(INDIRECT("'" & SUBSTITUTE($F$1,"'","''") & "'!C68"), "") -> 31 | H25: =IFERROR(INDIRECT("'" & SUBSTITUTE($H$1,"'","''") & "'!B68"), "") -> 27.1 | I25: =IFERROR(INDIRECT("'" & SUBSTITUTE($H$1,"'","''") & "'!C68"), "") -> 5 | J25: =IFERROR(INDIRECT("'" & SUBSTITUTE($J$1,"'","''") & "'!B68"), "") -> 15 | K25: =IFERROR(INDIRECT("'" & SUBSTITUTE($J$1,"'","''") & "'!C68"), "") -> 30 | L25: =IFERROR(INDIRECT("'" & SUBSTITUTE($L$1,"'","''") & "'!B68"), "") -> 26.2 | M25: =IFERROR(INDIRECT("'" & SUBSTITUTE($L$1,"'","''") & "'!C68"), "") -> 6 | N25: =IFERROR(INDIRECT("'" & SUBSTITUTE($N$1,"'","''") & "'!B68"), "") -> 16.6 | O25: =IFERROR(INDIRECT("'" & SUBSTITUTE($N$1,"'","''") & "'!C68"), "") -> 82 | P25: =IFERROR(INDIRECT("'" & SUBSTITUTE($P$1,"'","''") & "'!B68"), "") -> 17.6 | Q25: =IFERROR(INDIRECT("'" & SUBSTITUTE($P$1,"'","''") & "'!C68"), "") -> 71 | R25: =IFERROR(INDIRECT("'" & SUBSTITUTE($R$1,"'","''") & "'!B68"), "") -> 18.4 | S25: =IFERROR(INDIRECT("'" & SUBSTITUTE($R$1,"'","''") & "'!C68"), "") -> 62 | T25: =IFERROR(INDIRECT("'" & SUBSTITUTE($T$1,"'","''") & "'!B68"), "") -> 26.7 | U25: =IFERROR(INDIRECT("'" & SUBSTITUTE($T$1,"'","''") & "'!C68"), "") -> 10 | V25: =IFERROR(INDIRECT("'" & SUBSTITUTE($V$1,"'","''") & "'!B68"), "") -> 27.9 | W25: =IFERROR(INDIRECT("'" & SUBSTITUTE($V$1,"'","''") & "'!C68"), "") -> 2 | X25: =IFERROR(INDIRECT("'" & SUBSTITUTE($X$1,"'","''") & "'!B68"), "") -> 16.1 | Y25: =IFERROR(INDIRECT("'" & SUBSTITUTE($X$1,"'","''") & "'!C68"), "") -> 90
A26: Shots from Free Kicks | B26: =IFERROR(INDIRECT("'" & SUBSTITUTE($B$1,"'","''") & "'!B71"), "") -> 0 | C26: =IFERROR(INDIRECT("'" & SUBSTITUTE($B$1,"'","''") & "'!C71"), "") -> 34 | D26: =IFERROR(INDIRECT("'" & SUBSTITUTE($D$1,"'","''") & "'!B71"), "") -> 0 | E26: =IFERROR(INDIRECT("'" & SUBSTITUTE($D$1,"'","''") & "'!C71"), "") -> 34 | F26: =IFERROR(INDIRECT("'" & SUBSTITUTE($F$1,"'","''") & "'!B71"), "") -> 0.1 | G26: =IFERROR(INDIRECT("'" & SUBSTITUTE($F$1,"'","''") & "'!C71"), "") -> 87 | H26: =IFERROR(INDIRECT("'" & SUBSTITUTE($H$1,"'","''") & "'!B71"), "") -> 0 | I26: =IFERROR(INDIRECT("'" & SUBSTITUTE($H$1,"'","''") & "'!C71"), "") -> 34 | J26: =IFERROR(INDIRECT("'" & SUBSTITUTE($J$1,"'","''") & "'!B71"), "") -> 0 | K26: =IFERROR(INDIRECT("'" & SUBSTITUTE($J$1,"'","''") & "'!C71"), "") -> 44 | L26: =IFERROR(INDIRECT("'" & SUBSTITUTE($L$1,"'","''") & "'!B71"), "") -> 0.15 | M26: =IFERROR(INDIRECT("'" & SUBSTITUTE($L$1,"'","''") & "'!C71"), "") -> 86 | N26: =IFERROR(INDIRECT("'" & SUBSTITUTE($N$1,"'","''") & "'!B71"), "") -> 0 | O26: =IFERROR(INDIRECT("'" & SUBSTITUTE($N$1,"'","''") & "'!C71"), "") -> 33 | P26: =IFERROR(INDIRECT("'" & SUBSTITUTE($P$1,"'","''") & "'!B71"), "") -> 0.04 | Q26: =IFERROR(INDIRECT("'" & SUBSTITUTE($P$1,"'","''") & "'!C71"), "") -> 73 | R26: =IFERROR(INDIRECT("'" & SUBSTITUTE($R$1,"'","''") & "'!B71"), "") -> 0.15 | S26: =IFERROR(INDIRECT("'" & SUBSTITUTE($R$1,"'","''") & "'!C71"), "") -> 86 | T26: =IFERROR(INDIRECT("'" & SUBSTITUTE($T$1,"'","''") & "'!B71"), "") -> 0.33 | U26: =IFERROR(INDIRECT("'" & SUBSTITUTE($T$1,"'","''") & "'!C71"), "") -> 97 | V26: =IFERROR(INDIRECT("'" & SUBSTITUTE($V$1,"'","''") & "'!B71"), "") -> 0 | W26: =IFERROR(INDIRECT("'" & SUBSTITUTE($V$1,"'","''") & "'!C71"), "") -> 33 | X26: =IFERROR(INDIRECT("'" & SUBSTITUTE($X$1,"'","''") & "'!B71"), "") -> 0 | Y26: =IFERROR(INDIRECT("'" & SUBSTITUTE($X$1,"'","''") & "'!C71"), "") -> 32
A27: npxG/Shot | B27: =IFERROR(INDIRECT("'" & SUBSTITUTE($B$1,"'","''") & "'!B87"), "") -> 0.12 | C27: =IFERROR(INDIRECT("'" & SUBSTITUTE($B$1,"'","''") & "'!C87"), "") -> 89 | D27: =IFERROR(INDIRECT("'" & SUBSTITUTE($D$1,"'","''") & "'!B87"), "") -> 0.08 | E27: =IFERROR(INDIRECT("'" & SUBSTITUTE($D$1,"'","''") & "'!C87"), "") -> 61 | F27: =IFERROR(INDIRECT("'" & SUBSTITUTE($F$1,"'","''") & "'!B87"), "") -> 0.06 | G27: =IFERROR(INDIRECT("'" & SUBSTITUTE($F$1,"'","''") & "'!C87"), "") -> 36 | H27: =IFERROR(INDIRECT("'" & SUBSTITUTE($H$1,"'","''") & "'!B87"), "") -> 0.04 | I27: =IFERROR(INDIRECT("'" & SUBSTITUTE($H$1,"'","''") & "'!C87"), "") -> 10 | J27: =IFERROR(INDIRECT("'" & SUBSTITUTE($J$1,"'","''") & "'!B87"), "") -> 0.1 | K27: =IFERROR(INDIRECT("'" & SUBSTITUTE($J$1,"'","''") & "'!C87"), "") -> 59 | L27: =IFERROR(INDIRECT("'" & SUBSTITUTE($L$1,"'","''") & "'!B87"), "") -> 0.03 | M27: =IFERROR(INDIRECT("'" & SUBSTITUTE($L$1,"'","''") & "'!C87"), "") -> 6 | N27: =IFERROR(INDIRECT("'" & SUBSTITUTE($N$1,"'","''") & "'!B87"), "") -> 0.1 | O27: =IFERROR(INDIRECT("'" & SUBSTITUTE($N$1,"'","''") & "'!C87"), "") -> 76 | P27: =IFERROR(INDIRECT("'" & SUBSTITUTE($P$1,"'","''") & "'!B87"), "") -> 0.09 | Q27: =IFERROR(INDIRECT("'" & SUBSTITUTE($P$1,"'","''") & "'!C87"), "") -> 64 | R27: =IFERROR(INDIRECT("'" & SUBSTITUTE($R$1,"'","''") & "'!B87"), "") -> 0.08 | S27: =IFERROR(INDIRECT("'" & SUBSTITUTE($R$1,"'","''") & "'!C87"), "") -> 50 | T27: =IFERROR(INDIRECT("'" & SUBSTITUTE($T$1,"'","''") & "'!B87"), "") -> 0.04 | U27: =IFERROR(INDIRECT("'" & SUBSTITUTE($T$1,"'","''") & "'!C87"), "") -> 13 | V27: =IFERROR(INDIRECT("'" & SUBSTITUTE($V$1,"'","''") & "'!B87"), "") -> 0.03 | W27: =IFERROR(INDIRECT("'" & SUBSTITUTE($V$1,"'","''") & "'!C87"), "") -> 6 | X27: =IFERROR(INDIRECT("'" & SUBSTITUTE($X$1,"'","''") & "'!B87"), "") -> 0.1 | Y27: =IFERROR(INDIRECT("'" & SUBSTITUTE($X$1,"'","''") & "'!C87"), "") -> 82
A28: Goals - xG | B28: =IFERROR(INDIRECT("'" & SUBSTITUTE($B$1,"'","''") & "'!B90"), "") -> -0.06 | C28: =IFERROR(INDIRECT("'" & SUBSTITUTE($B$1,"'","''") & "'!C90"), "") -> 7 | D28: =IFERROR(INDIRECT("'" & SUBSTITUTE($D$1,"'","''") & "'!B90"), "") -> -0.02 | E28: =IFERROR(INDIRECT("'" & SUBSTITUTE($D$1,"'","''") & "'!C90"), "") -> 29 | F28: =IFERROR(INDIRECT("'" & SUBSTITUTE($F$1,"'","''") & "'!B90"), "") -> -0.03 | G28: =IFERROR(INDIRECT("'" & SUBSTITUTE($F$1,"'","''") & "'!C90"), "") -> 23 | H28: =IFERROR(INDIRECT("'" & SUBSTITUTE($H$1,"'","''") & "'!B90"), "") -> -0.01 | I28: =IFERROR(INDIRECT("'" & SUBSTITUTE($H$1,"'","''") & "'!C90"), "") -> 41 | J28: =IFERROR(INDIRECT("'" & SUBSTITUTE($J$1,"'","''") & "'!B90"), "") -> 0.02 | K28: =IFERROR(INDIRECT("'" & SUBSTITUTE($J$1,"'","''") & "'!C90"), "") -> 77 | L28: =IFERROR(INDIRECT("'" & SUBSTITUTE($L$1,"'","''") & "'!B90"), "") -> -0.03 | M28: =IFERROR(INDIRECT("'" & SUBSTITUTE($L$1,"'","''") & "'!C90"), "") -> 36 | N28: =IFERROR(INDIRECT("'" & SUBSTITUTE($N$1,"'","''") & "'!B90"), "") -> -0.02 | O28: =IFERROR(INDIRECT("'" & SUBSTITUTE($N$1,"'","''") & "'!C90"), "") -> 45 | P28: =IFERROR(INDIRECT("'" & SUBSTITUTE($P$1,"'","''") & "'!B90"), "") -> -0.05 | Q28: =IFERROR(INDIRECT("'" & SUBSTITUTE($P$1,"'","''") & "'!C90"), "") -> 22 | R28: =IFERROR(INDIRECT("'" & SUBSTITUTE($R$1,"'","''") & "'!B90"), "") -> -0.07 | S28: =IFERROR(INDIRECT("'" & SUBSTITUTE($R$1,"'","''") & "'!C90"), "") -> 16 | T28: =IFERROR(INDIRECT("'" & SUBSTITUTE($T$1,"'","''") & "'!B90"), "") -> 0.02 | U28: =IFERROR(INDIRECT("'" & SUBSTITUTE($T$1,"'","''") & "'!C90"), "") -> 62 | V28: =IFERROR(INDIRECT("'" & SUBSTITUTE($V$1,"'","''") & "'!B90"), "") -> -0.03 | W28: =IFERROR(INDIRECT("'" & SUBSTITUTE($V$1,"'","''") & "'!C90"), "") -> 34 | X28: =IFERROR(INDIRECT("'" & SUBSTITUTE($X$1,"'","''") & "'!B90"), "") -> -0.01 | Y28: =IFERROR(INDIRECT("'" & SUBSTITUTE($X$1,"'","''") & "'!C90"), "") -> 50
A29: Non-Penalty Goals - npxG | B29: =IFERROR(INDIRECT("'" & SUBSTITUTE($B$1,"'","''") & "'!B93"), "") -> -0.06 | C29: =IFERROR(INDIRECT("'" & SUBSTITUTE($B$1,"'","''") & "'!C93"), "") -> 7 | D29: =IFERROR(INDIRECT("'" & SUBSTITUTE($D$1,"'","''") & "'!B93"), "") -> -0.02 | E29: =IFERROR(INDIRECT("'" & SUBSTITUTE($D$1,"'","''") & "'!C93"), "") -> 28 | F29: =IFERROR(INDIRECT("'" & SUBSTITUTE($F$1,"'","''") & "'!B93"), "") -> -0.03 | G29: =IFERROR(INDIRECT("'" & SUBSTITUTE($F$1,"'","''") & "'!C93"), "") -> 22 | H29: =IFERROR(INDIRECT("'" & SUBSTITUTE($H$1,"'","''") & "'!B93"), "") -> -0.01 | I29: =IFERROR(INDIRECT("'" & SUBSTITUTE($H$1,"'","''") & "'!C93"), "") -> 40 | J29: =IFERROR(INDIRECT("'" & SUBSTITUTE($J$1,"'","''") & "'!B93"), "") -> 0.02 | K29: =IFERROR(INDIRECT("'" & SUBSTITUTE($J$1,"'","''") & "'!C93"), "") -> 77 | L29: =IFERROR(INDIRECT("'" & SUBSTITUTE($L$1,"'","''") & "'!B93"), "") -> -0.03 | M29: =IFERROR(INDIRECT("'" & SUBSTITUTE($L$1,"'","''") & "'!C93"), "") -> 36 | N29: =IFERROR(INDIRECT("'" & SUBSTITUTE($N$1,"'","''") & "'!B93"), "") -> -0.02 | O29: =IFERROR(INDIRECT("'" & SUBSTITUTE($N$1,"'","''") & "'!C93"), "") -> 46 | P29: =IFERROR(INDIRECT("'" & SUBSTITUTE($P$1,"'","''") & "'!B93"), "") -> -0.05 | Q29: =IFERROR(INDIRECT("'" & SUBSTITUTE($P$1,"'","''") & "'!C93"), "") -> 22 | R29: =IFERROR(INDIRECT("'" & SUBSTITUTE($R$1,"'","''") & "'!B93"), "") -> -0.07 | S29: =IFERROR(INDIRECT("'" & SUBSTITUTE($R$1,"'","''") & "'!C93"), "") -> 17 | T29: =IFERROR(INDIRECT("'" & SUBSTITUTE($T$1,"'","''") & "'!B93"), "") -> 0.01 | U29: =IFERROR(INDIRECT("'" & SUBSTITUTE($T$1,"'","''") & "'!C93"), "") -> 60 | V29: =IFERROR(INDIRECT("'" & SUBSTITUTE($V$1,"'","''") & "'!B93"), "") -> -0.03 | W29: =IFERROR(INDIRECT("'" & SUBSTITUTE($V$1,"'","''") & "'!C93"), "") -> 34 | X29: =IFERROR(INDIRECT("'" & SUBSTITUTE($X$1,"'","''") & "'!B93"), "") -> -0.01 | Y29: =IFERROR(INDIRECT("'" & SUBSTITUTE($X$1,"'","''") & "'!C93"), "") -> 49
A30: Passes Completed | B30: =IFERROR(INDIRECT("'" & SUBSTITUTE($B$1,"'","''") & "'!B98"), "") -> 12.31 | C30: =IFERROR(INDIRECT("'" & SUBSTITUTE($B$1,"'","''") & "'!C98"), "") -> 1 | D30: =IFERROR(INDIRECT("'" & SUBSTITUTE($D$1,"'","''") & "'!B98"), "") -> 44.03 | E30: =IFERROR(INDIRECT("'" & SUBSTITUTE($D$1,"'","''") & "'!C98"), "") -> 60 | F30: =IFERROR(INDIRECT("'" & SUBSTITUTE($F$1,"'","''") & "'!B98"), "") -> 27.42 | G30: =IFERROR(INDIRECT("'" & SUBSTITUTE($F$1,"'","''") & "'!C98"), "") -> 11 | H30: =IFERROR(INDIRECT("'" & SUBSTITUTE($H$1,"'","''") & "'!B98"), "") -> 45 | I30: =IFERROR(INDIRECT("'" & SUBSTITUTE($H$1,"'","''") & "'!C98"), "") -> 63 | J30: =IFERROR(INDIRECT("'" & SUBSTITUTE($J$1,"'","''") & "'!B98"), "") -> 63.31 | K30: =IFERROR(INDIRECT("'" & SUBSTITUTE($J$1,"'","''") & "'!C98"), "") -> 86 | L30: =IFERROR(INDIRECT("'" & SUBSTITUTE($L$1,"'","''") & "'!B98"), "") -> 58.99 | M30: =IFERROR(INDIRECT("'" & SUBSTITUTE($L$1,"'","''") & "'!C98"), "") -> 86 | N30: =IFERROR(INDIRECT("'" & SUBSTITUTE($N$1,"'","''") & "'!B98"), "") -> 38.24 | O30: =IFERROR(INDIRECT("'" & SUBSTITUTE($N$1,"'","''") & "'!C98"), "") -> 55 | P30: =IFERROR(INDIRECT("'" & SUBSTITUTE($P$1,"'","''") & "'!B98"), "") -> 29.84 | Q30: =IFERROR(INDIRECT("'" & SUBSTITUTE($P$1,"'","''") & "'!C98"), "") -> 27 | R30: =IFERROR(INDIRECT("'" & SUBSTITUTE($R$1,"'","''") & "'!B98"), "") -> 42.98 | S30: =IFERROR(INDIRECT("'" & SUBSTITUTE($R$1,"'","''") & "'!C98"), "") -> 67 | T30: =IFERROR(INDIRECT("'" & SUBSTITUTE($T$1,"'","''") & "'!B98"), "") -> 51.57 | U30: =IFERROR(INDIRECT("'" & SUBSTITUTE($T$1,"'","''") & "'!C98"), "") -> 81 | V30: =IFERROR(INDIRECT("'" & SUBSTITUTE($V$1,"'","''") & "'!B98"), "") -> 42.09 | W30: =IFERROR(INDIRECT("'" & SUBSTITUTE($V$1,"'","''") & "'!C98"), "") -> 61 | X30: =IFERROR(INDIRECT("'" & SUBSTITUTE($X$1,"'","''") & "'!B98"), "") -> 32.72 | Y30: =IFERROR(INDIRECT("'" & SUBSTITUTE($X$1,"'","''") & "'!C98"), "") -> 45
A31: Passes Attempted | B31: =IFERROR(INDIRECT("'" & SUBSTITUTE($B$1,"'","''") & "'!B101"), "") -> 18.87 | C31: =IFERROR(INDIRECT("'" & SUBSTITUTE($B$1,"'","''") & "'!C101"), "") -> 1 | D31: =IFERROR(INDIRECT("'" & SUBSTITUTE($D$1,"'","''") & "'!B101"), "") -> 51.6 | E31: =IFERROR(INDIRECT("'" & SUBSTITUTE($D$1,"'","''") & "'!C101"), "") -> 59 | F31: =IFERROR(INDIRECT("'" & SUBSTITUTE($F$1,"'","''") & "'!B101"), "") -> 35.21 | G31: =IFERROR(INDIRECT("'" & SUBSTITUTE($F$1,"'","''") & "'!C101"), "") -> 10 | H31: =IFERROR(INDIRECT("'" & SUBSTITUTE($H$1,"'","''") & "'!B101"), "") -> 48.81 | I31: =IFERROR(INDIRECT("'" & SUBSTITUTE($H$1,"'","''") & "'!C101"), "") -> 49 | J31: =IFERROR(INDIRECT("'" & SUBSTITUTE($J$1,"'","''") & "'!B101"), "") -> 70.74 | K31: =IFERROR(INDIRECT("'" & SUBSTITUTE($J$1,"'","''") & "'!C101"), "") -> 87 | L31: =IFERROR(INDIRECT("'" & SUBSTITUTE($L$1,"'","''") & "'!B101"), "") -> 70.34 | M31: =IFERROR(INDIRECT("'" & SUBSTITUTE($L$1,"'","''") & "'!C101"), "") -> 88 | N31: =IFERROR(INDIRECT("'" & SUBSTITUTE($N$1,"'","''") & "'!B101"), "") -> 44.58 | O31: =IFERROR(INDIRECT("'" & SUBSTITUTE($N$1,"'","''") & "'!C101"), "") -> 48 | P31: =IFERROR(INDIRECT("'" & SUBSTITUTE($P$1,"'","''") & "'!B101"), "") -> 37.5 | Q31: =IFERROR(INDIRECT("'" & SUBSTITUTE($P$1,"'","''") & "'!C101"), "") -> 23 | R31: =IFERROR(INDIRECT("'" & SUBSTITUTE($R$1,"'","''") & "'!B101"), "") -> 53.44 | S31: =IFERROR(INDIRECT("'" & SUBSTITUTE($R$1,"'","''") & "'!C101"), "") -> 70 | T31: =IFERROR(INDIRECT("'" & SUBSTITUTE($T$1,"'","''") & "'!B101"), "") -> 62.78 | U31: =IFERROR(INDIRECT("'" & SUBSTITUTE($T$1,"'","''") & "'!C101"), "") -> 84 | V31: =IFERROR(INDIRECT("'" & SUBSTITUTE($V$1,"'","''") & "'!B101"), "") -> 50 | W31: =IFERROR(INDIRECT("'" & SUBSTITUTE($V$1,"'","''") & "'!C101"), "") -> 59 | X31: =IFERROR(INDIRECT("'" & SUBSTITUTE($X$1,"'","''") & "'!B101"), "") -> 37.94 | Y31: =IFERROR(INDIRECT("'" & SUBSTITUTE($X$1,"'","''") & "'!C101"), "") -> 31
A32: Pass Completion % | B32: =IFERROR(INDIRECT("'" & SUBSTITUTE($B$1,"'","''") & "'!B104"), "") -> 0.652 | C32: =IFERROR(INDIRECT("'" & SUBSTITUTE($B$1,"'","''") & "'!C104"), "") -> 1 | D32: =IFERROR(INDIRECT("'" & SUBSTITUTE($D$1,"'","''") & "'!B104"), "") -> 0.853 | E32: =IFERROR(INDIRECT("'" & SUBSTITUTE($D$1,"'","''") & "'!C104"), "") -> 58 | F32: =IFERROR(INDIRECT("'" & SUBSTITUTE($F$1,"'","''") & "'!B104"), "") -> 0.779 | G32: =IFERROR(INDIRECT("'" & SUBSTITUTE($F$1,"'","''") & "'!C104"), "") -> 15 | H32: =IFERROR(INDIRECT("'" & SUBSTITUTE($H$1,"'","''") & "'!B104"), "") -> 0.922 | I32: =IFERROR(INDIRECT("'" & SUBSTITUTE($H$1,"'","''") & "'!C104"), "") -> 96 | J32: =IFERROR(INDIRECT("'" & SUBSTITUTE($J$1,"'","''") & "'!B104"), "") -> 0.895 | K32: =IFERROR(INDIRECT("'" & SUBSTITUTE($J$1,"'","''") & "'!C104"), "") -> 71 | L32: =IFERROR(INDIRECT("'" & SUBSTITUTE($L$1,"'","''") & "'!B104"), "") -> 0.839 | M32: =IFERROR(INDIRECT("'" & SUBSTITUTE($L$1,"'","''") & "'!C104"), "") -> 60 | N32: =IFERROR(INDIRECT("'" & SUBSTITUTE($N$1,"'","''") & "'!B104"), "") -> 0.858 | O32: =IFERROR(INDIRECT("'" & SUBSTITUTE($N$1,"'","''") & "'!C104"), "") -> 73 | P32: =IFERROR(INDIRECT("'" & SUBSTITUTE($P$1,"'","''") & "'!B104"), "") -> 0.796 | Q32: =IFERROR(INDIRECT("'" & SUBSTITUTE($P$1,"'","''") & "'!C104"), "") -> 45 | R32: =IFERROR(INDIRECT("'" & SUBSTITUTE($R$1,"'","''") & "'!B104"), "") -> 0.804 | S32: =IFERROR(INDIRECT("'" & SUBSTITUTE($R$1,"'","''") & "'!C104"), "") -> 52 | T32: =IFERROR(INDIRECT("'" & SUBSTITUTE($T$1,"'","''") & "'!B104"), "") -> 0.821 | U32: =IFERROR(INDIRECT("'" & SUBSTITUTE($T$1,"'","''") & "'!C104"), "") -> 60 | V32: =IFERROR(INDIRECT("'" & SUBSTITUTE($V$1,"'","''") & "'!B104"), "") -> 0.842 | W32: =IFERROR(INDIRECT("'" & SUBSTITUTE($V$1,"'","''") & "'!C104"), "") -> 63 | X32: =IFERROR(INDIRECT("'" & SUBSTITUTE($X$1,"'","''") & "'!B104"), "") -> 0.863 | Y32: =IFERROR(INDIRECT("'" & SUBSTITUTE($X$1,"'","''") & "'!C104"), "") -> 83
